<?xml version="1.0"?>
<!-- created with Phobos 1.0.1 "Capricious Choutengan" -->
  <robot name="rhea">

    <link name="base_link">
      <inertial>
        <origin xyz="0 0 0" rpy="0 0 0"/>
        <mass value="3.0"/>
        <inertia ixx="0.01" ixy="0" ixz="0" iyy="0.01" iyz="0" izz="0.01"/>
      </inertial>
      <visual name="rhea_mesh">
        <origin xyz="0 0 0" rpy="0 0 0"/>
        <geometry>
          <mesh filename="../meshes/dae/simple_bot_mesh.dae" scale="1.0 1.0 1.0"/>
        </geometry>
        <material name="Aluminum_-_Anodized_Rough_(Grey)_1"/>
      </visual>
      <collision name="Cube">
        <origin xyz="0 0 0" rpy="0 0 0"/>
        <geometry>
          <box size="0.24 0.14 0.22"/>
        </geometry>
      </collision>
      <!-- <collision name="Cube">
        <origin xyz="-0.08 0 0" rpy="0 0 0"/>
        <geometry>
          <box size="0.42 0.14 0.22"/>
        </geometry>
      </collision> -->
    </link>

    <link name="left_leg">
      <inertial>
        <origin xyz="0 0 0" rpy="0 0 0"/>
        <mass value="0.1"/>
        <inertia ixx="0.001" ixy="0" ixz="0" iyy="0.001" iyz="0" izz="0.001"/>
      </inertial>
    </link>

    <link name="left_wheel">
      <inertial>
        <origin xyz="0 0 0" rpy="0 0 0"/>
        <mass value="0.4"/>
        <inertia ixx="0.001" ixy="0" ixz="0" iyy="0.001" iyz="0" izz="0.001"/>
      </inertial>
      <visual name="rhea_mesh.004">
        <origin xyz="0 0 0" rpy="1.5708 0 -1.0472"/>
        <geometry>
          <mesh filename="../meshes/dae/simple_bot_mesh.004.dae" scale="1.0 1.0 1.0"/>
        </geometry>
        <material name="Aluminum_-_Anodized_Rough_(Grey)"/>
      </visual>
      <!-- <collision name="Cylinder.003">
        <origin xyz="0 0 0.0415" rpy="0 0 -1.0472"/>
        <geometry>
          <sphere radius="0.1"/>
        </geometry>
      </collision>       -->
      <collision name="Cylinder.003">
        <origin xyz="0 0 0.0415" rpy="0 0 -1.0472"/>
        <geometry>
          <cylinder radius="0.1" length="0.024"/>
        </geometry>
      </collision>
    </link>

    <link name="right_leg">
      <inertial>
        <origin xyz="0 0 0" rpy="0 0 0"/>
        <mass value="0.1"/>
        <inertia ixx="0.001" ixy="0" ixz="0" iyy="0.001" iyz="0" izz="0.001"/>
      </inertial>
    </link>

    <link name="right_wheel">
      <inertial>
        <origin xyz="0 0 0" rpy="0 0 0"/>
        <mass value="0.4"/>
        <inertia ixx="0.001" ixy="0" ixz="0" iyy="0.001" iyz="0" izz="0.001"/>
      </inertial>
      <visual name="rhea_mesh.001">
        <origin xyz="0 0 0" rpy="-1.5708 0 1.0472"/>
        <geometry>
          <mesh filename="../meshes/dae/simple_bot_mesh.001.dae" scale="1.0 1.0 1.0"/>
        </geometry>
        <material name="Aluminum_-_Anodized_Rough_(Grey)"/>
      </visual>
      <!-- <collision name="Cylinder.001">
        <origin xyz="0 0 0.0415" rpy="0 0 1.0472"/>
        <geometry>
          <sphere radius="0.1"/>
        </geometry>
      </collision> -->
      <collision name="Cylinder.001">
        <origin xyz="0 0 0.0415" rpy="0 0 1.0472"/>
        <geometry>
          <cylinder radius="0.1" length="0.024"/>
        </geometry>
      </collision>
    </link>

    <joint name="left_leg" type="prismatic">
      <origin xyz="0 0.1 0" rpy="0 0 3.1415"/>
      <parent link="base_link"/>
      <child link="left_leg"/>
      <axis xyz="0 0 1.0"/>
      <limit lower="-0.35" upper="-0.075" effort="100.0" velocity="1.0"/>
    </joint>

    <joint name="left_wheel" type="revolute">
      <origin xyz="0 0 0" rpy="1.5708 1.5708 0"/>
      <parent link="left_leg"/>
      <child link="left_wheel"/>
      <axis xyz="0 0 1.0"/>
      <limit lower="-100000" upper="100000" effort="9.0" velocity="42.0"/>
    </joint>

    <joint name="right_leg" type="prismatic">
      <origin xyz="0 -0.1 0" rpy="0 0 0"/>
      <parent link="base_link"/>
      <child link="right_leg"/>
      <axis xyz="0 0 1.0"/>
      <limit lower="-0.35" upper="-0.075" effort="100.0" velocity="1.0"/>
    </joint>

    <joint name="right_wheel" type="revolute">
      <origin xyz="0 0 0" rpy="1.5708 1.5708 0"/>
      <parent link="right_leg"/>
      <child link="right_wheel"/>
      <axis xyz="0 0 1.0"/>
      <limit lower="-100000" upper="100000" effort="9.0" velocity="42.0"/>
    </joint>

    <material name="Aluminum_-_Anodized_Rough_(Grey)">
      <color rgba="0.28627 0.28627 0.28627 1.0"/>
    </material>

    <material name="Aluminum_-_Anodized_Rough_(Grey)_1">
      <color rgba="0.28627 0.28627 0.28627 1.0"/>
    </material>

    <material name="PA_12_-_Nylon_-_PA_603-CF_(with_EOS_P_3D_Printers)">
      <color rgba="0.24706 0.24706 0.24706 1.0"/>
    </material>

  </robot>
