<?xml version="1.0"?>
<!-- created with Phobos 1.0.1 "Capricious Choutengan" -->
  <robot name="pupper_v3">

    <link name="base_link">
      <inertial>
        <origin xyz="9e-03 0 0.02177" rpy="0 0 0"/>
        <mass value="1.2"/>
        <inertia ixx="0.02" ixy="0" ixz="0" iyy="0.02" iyz="0" izz="0.02"/>
      </inertial>
      <visual name="pupperv3_export">
        <origin xyz="0 0 0" rpy="0 0 0"/>
        <geometry>
          <mesh filename="../meshes/dae/pupperv3_export.dae" scale="1.0 1.0 1.0"/>
        </geometry>
        <material name="Plastic_-_Matte_(Gray)"/>
      </visual>
      <collision name="ProtoAssembly-MG v25.004">
        <origin xyz="0.02009 0 0.03177" rpy="1.5708 0 0"/>
        <geometry>
          <box size="0.26419 0.13252 0.115"/>
        </geometry>
      </collision>
    </link>

    <link name="leg_back_l_1">
      <inertial>
        <origin xyz="0.00263 8e-03 0.03455" rpy="0 0 0"/>
        <mass value="0.16"/>
        <inertia ixx="0.0012" ixy="0" ixz="0" iyy="2e-03" iyz="0" izz="3e-03"/>
      </inertial>
      <visual name="pupperv3_export.011">
        <origin xyz="0.075 0 -0.05" rpy="1.5708 0 0"/>
        <geometry>
          <mesh filename="../meshes/dae/pupperv3_export.011.dae" scale="1.0 1.0 1.0"/>
        </geometry>
        <material name="Plastic_-_Matte_(Gray)"/>
      </visual>
    </link>

    <link name="leg_back_l_2">
      <inertial>
        <origin xyz="0.0461 0.00255 -0.05754" rpy="0 0 0"/>
        <mass value="0.02"/>
        <inertia ixx="2e-03" ixy="0" ixz="0" iyy="2e-03" iyz="0" izz="4e-03"/>
      </inertial>
      <visual name="pupperv3_export.006">
        <origin xyz="0 -0.084 0.075" rpy="0 -1.5708 0"/>
        <geometry>
          <mesh filename="../meshes/dae/pupperv3_export.006.dae" scale="1.0 1.0 1.0"/>
        </geometry>
        <material name="Plastic_-_Matte_(Gray)"/>
      </visual>
    </link>

    <link name="leg_back_l_3">
      <inertial>
        <origin xyz="-0.08114 0.0073 -0.01746" rpy="0 0 0"/>
        <mass value="0.045"/>
        <inertia ixx="2e-03" ixy="0" ixz="0" iyy="2e-03" iyz="0" izz="2e-03"/>
      </inertial>
      <visual name="pupperv3_export.004">
        <origin xyz="-0.07797 -0.13266 0.084" rpy="-1.5708 0 -2.44346"/>
        <geometry>
          <mesh filename="../meshes/dae/pupperv3_export.004.dae" scale="1.0 1.0 1.0"/>
        </geometry>
        <material name="Plastic_-_Matte_(White)"/>
      </visual>
      <collision name="ProtoAssembly-MGv25.017">
        <origin xyz="-0.08746 0.0107 -0.0189" rpy="0 3.14159 0"/>
        <geometry>
          <sphere radius="0.01984"/>
        </geometry>
      </collision>
    </link>

    <link name="leg_back_r_1">
      <inertial>
        <origin xyz="0.00272 -1e-03 0.03409" rpy="0 0 0"/>
        <mass value="0.16"/>
        <inertia ixx="6e-03" ixy="0" ixz="0" iyy="1e-03" iyz="0" izz="1e-03"/>
      </inertial>
      <visual name="pupperv3_export.010">
        <origin xyz="0.075 0 -0.05" rpy="-1.5708 0 0"/>
        <geometry>
          <mesh filename="../meshes/dae/pupperv3_export.010.dae" scale="1.0 1.0 1.0"/>
        </geometry>
        <material name="Plastic_-_Matte_(Gray)"/>
      </visual>
    </link>

    <link name="leg_back_r_2">
      <inertial>
        <origin xyz="-0.04555 -0.00233 0.05745" rpy="0 0 0"/>
        <mass value="0.02"/>
        <inertia ixx="2e-03" ixy="0" ixz="0" iyy="2e-03" iyz="0" izz="4e-03"/>
      </inertial>
      <visual name="pupperv3_export.007">
        <origin xyz="0 0.084 -0.075" rpy="0 1.5708 0"/>
        <geometry>
          <mesh filename="../meshes/dae/pupperv3_export.007.dae" scale="1.0 1.0 1.0"/>
        </geometry>
        <material name="Plastic_-_Matte_(Gray)"/>
      </visual>
    </link>

    <link name="leg_back_r_3">
      <inertial>
        <origin xyz="0.08114 -0.0073 0.01746" rpy="0 0 0"/>
        <mass value="0.045"/>
        <inertia ixx="2e-03" ixy="0" ixz="0" iyy="2e-03" iyz="0" izz="2e-03"/>
      </inertial>
      <visual name="pupperv3_export.002">
        <origin xyz="0.07797 0.13266 -0.084" rpy="-1.5708 0 0.69813"/>
        <geometry>
          <mesh filename="../meshes/dae/pupperv3_export.002.dae" scale="1.0 1.0 1.0"/>
        </geometry>
        <material name="Plastic_-_Matte_(White)"/>
      </visual>
      <collision name="ProtoAssembly-MGv25.009">
        <origin xyz="0.08746 -0.0107 0.0189" rpy="0 0 0"/>
        <geometry>
          <sphere radius="0.01984"/>
        </geometry>
      </collision>
    </link>

    <link name="leg_front_l_1">
      <inertial>
        <origin xyz="0.00263 8e-03 0.03455" rpy="0 0 0"/>
        <mass value="0.16"/>
        <inertia ixx="0.0012" ixy="0" ixz="0" iyy="2e-03" iyz="0" izz="3e-03"/>
      </inertial>
      <visual name="pupperv3_export.012">
        <origin xyz="-0.075 0 -0.05" rpy="1.5708 0 0"/>
        <geometry>
          <mesh filename="../meshes/dae/pupperv3_export.012.dae" scale="1.0 1.0 1.0"/>
        </geometry>
        <material name="Plastic_-_Matte_(Gray)"/>
      </visual>
    </link>

    <link name="leg_front_l_2">
      <inertial>
        <origin xyz="0.0461 0.00255 -0.05754" rpy="0 0 0"/>
        <mass value="0.17"/>
        <inertia ixx="2e-03" ixy="0" ixz="0" iyy="2e-03" iyz="0" izz="4e-03"/>
      </inertial>
      <visual name="pupperv3_export.005">
        <origin xyz="0 -0.084 -0.075" rpy="0 -1.5708 0"/>
        <geometry>
          <mesh filename="../meshes/dae/pupperv3_export.005.dae" scale="1.0 1.0 1.0"/>
        </geometry>
        <material name="Steel_-_Satin"/>
      </visual>
    </link>

    <link name="leg_front_l_3">
      <inertial>
        <origin xyz="-0.08114 0.0073 -0.01746" rpy="0 0 0"/>
        <mass value="0.045"/>
        <inertia ixx="2e-03" ixy="0" ixz="0" iyy="2e-03" iyz="0" izz="2e-03"/>
      </inertial>
      <visual name="pupperv3_export.003">
        <origin xyz="0.03694 -0.03624 0.084" rpy="-1.5708 0 -2.44346"/>
        <geometry>
          <mesh filename="../meshes/dae/pupperv3_export.003.dae" scale="1.0 1.0 1.0"/>
        </geometry>
        <material name="Polyurethane"/>
      </visual>
      <collision name="ProtoAssembly-MGv25.013">
        <origin xyz="-0.08746 0.0107 -0.0189" rpy="0 3.14159 0"/>
        <geometry>
          <sphere radius="0.01984"/>
        </geometry>
      </collision>
    </link>

    <link name="leg_front_r_1">
      <inertial>
        <origin xyz="0.00272 -1e-03 0.03409" rpy="0 0 0"/>
        <mass value="0.16"/>
        <inertia ixx="6e-03" ixy="0" ixz="0" iyy="1e-03" iyz="0" izz="1e-03"/>
      </inertial>
      <visual name="pupperv3_export.009">
        <origin xyz="-0.075 0 -0.05" rpy="-1.5708 0 0"/>
        <geometry>
          <mesh filename="../meshes/dae/pupperv3_export.009.dae" scale="1.0 1.0 1.0"/>
        </geometry>
        <material name="Plastic_-_Matte_(Gray)"/>
      </visual>
    </link>

    <link name="leg_front_r_2">
      <inertial>
        <origin xyz="-0.04555 -0.00233 0.05745" rpy="0 0 0"/>
        <mass value="0.02"/>
        <inertia ixx="2e-03" ixy="0" ixz="0" iyy="2e-03" iyz="0" izz="4e-03"/>
      </inertial>
      <visual name="pupperv3_export.008">
        <origin xyz="0 0.084 0.075" rpy="0 1.5708 0"/>
        <geometry>
          <mesh filename="../meshes/dae/pupperv3_export.008.dae" scale="1.0 1.0 1.0"/>
        </geometry>
        <material name="Plastic_-_Matte_(Gray)"/>
      </visual>
    </link>

    <link name="leg_front_r_3">
      <inertial>
        <origin xyz="0.08114 -0.0073 0.01746" rpy="0 0 0"/>
        <mass value="0.045"/>
        <inertia ixx="2e-03" ixy="0" ixz="0" iyy="2e-03" iyz="0" izz="2e-03"/>
      </inertial>
      <visual name="pupperv3_export.001">
        <origin xyz="-0.03694 0.03624 -0.084" rpy="-1.5708 0 0.69813"/>
        <geometry>
          <mesh filename="../meshes/dae/pupperv3_export.001.dae" scale="1.0 1.0 1.0"/>
        </geometry>
        <material name="ABS_(White)"/>
      </visual>
      <collision name="ProtoAssembly-MGv25.005">
        <origin xyz="0.08746 -0.0107 0.0189" rpy="0 0 0"/>
        <geometry>
          <sphere radius="0.01984"/>
        </geometry>
      </collision>
    </link>

    <joint name="leg_back_l_1" type="revolute">
      <origin xyz="-0.075 0.05 0" rpy="-1.5708 0 0"/>
      <parent link="base_link"/>
      <child link="leg_back_l_1"/>
      <axis xyz="0 0 1.0"/>
      <limit lower="-2.87979" upper="2.35619" effort="3.7" velocity="47.12389"/>
    </joint>

    <joint name="leg_back_l_2" type="revolute">
      <origin xyz="0 0 0.034" rpy="1.5708 0 1.5708"/>
      <parent link="leg_back_l_1"/>
      <child link="leg_back_l_2"/>
      <axis xyz="0 0 -1.0"/>
      <limit lower="-1.5708" upper="0.69813" effort="3.7" velocity="47.12389"/>
    </joint>

    <joint name="leg_back_l_3" type="revolute">
      <origin xyz="0.0515 0 -0.07" rpy="1.5708 2.26893 0"/>
      <parent link="leg_back_l_2"/>
      <child link="leg_back_l_3"/>
      <axis xyz="0 0 -1.0"/>
      <limit lower="-1.20428" upper="3.14159" effort="3.7" velocity="47.12389"/>
    </joint>

    <joint name="leg_back_r_1" type="revolute">
      <origin xyz="-0.075 -0.05 0" rpy="1.5708 0 0"/>
      <parent link="base_link"/>
      <child link="leg_back_r_1"/>
      <axis xyz="0 0 1.0"/>
      <limit lower="-2.35619" upper="2.87979" effort="3.7" velocity="47.12389"/>
    </joint>

    <joint name="leg_back_r_2" type="revolute">
      <origin xyz="0 0 0.034" rpy="-1.5708 0 1.5708"/>
      <parent link="leg_back_r_1"/>
      <child link="leg_back_r_2"/>
      <axis xyz="0 0 1.0"/>
      <limit lower="-0.69813" upper="1.5708" effort="3.7" velocity="47.12389"/>
    </joint>

    <joint name="leg_back_r_3" type="revolute">
      <origin xyz="-0.0515 0 0.07" rpy="1.5708 2.26893 0"/>
      <parent link="leg_back_r_2"/>
      <child link="leg_back_r_3"/>
      <axis xyz="0 0 1.0"/>
      <limit lower="-3.14159" upper="1.20428" effort="3.7" velocity="47.12389"/>
    </joint>

    <joint name="leg_front_l_1" type="revolute">
      <origin xyz="0.075 0.05 0" rpy="-1.5708 0 0"/>
      <parent link="base_link"/>
      <child link="leg_front_l_1"/>
      <axis xyz="0 0 1.0"/>
      <limit lower="-2.87979" upper="2.35619" effort="3.7" velocity="47.12389"/>
    </joint>

    <joint name="leg_front_l_2" type="revolute">
      <origin xyz="0 0 0.034" rpy="1.5708 0 1.5708"/>
      <parent link="leg_front_l_1"/>
      <child link="leg_front_l_2"/>
      <axis xyz="0 0 -1.0"/>
      <limit lower="-1.5708" upper="0.69813" effort="3.7" velocity="47.12389"/>
    </joint>

    <joint name="leg_front_l_3" type="revolute">
      <origin xyz="0.0515 0 -0.07" rpy="1.5708 2.26893 0"/>
      <parent link="leg_front_l_2"/>
      <child link="leg_front_l_3"/>
      <axis xyz="0 0 -1.0"/>
      <limit lower="-1.20428" upper="3.14159" effort="3.7" velocity="47.12389"/>
    </joint>

    <joint name="leg_front_r_1" type="revolute">
      <origin xyz="0.075 -0.05 0" rpy="1.5708 0 0"/>
      <parent link="base_link"/>
      <child link="leg_front_r_1"/>
      <axis xyz="0 0 1.0"/>
      <limit lower="-2.35619" upper="2.87979" effort="3.7" velocity="47.12389"/>
    </joint>

    <joint name="leg_front_r_2" type="revolute">
      <origin xyz="0 0 0.034" rpy="-1.5708 0 1.5708"/>
      <parent link="leg_front_r_1"/>
      <child link="leg_front_r_2"/>
      <axis xyz="0 0 1.0"/>
      <limit lower="-0.69813" upper="1.5708" effort="3.7" velocity="47.12389"/>
    </joint>

    <joint name="leg_front_r_3" type="revolute">
      <origin xyz="-0.0515 0 0.07" rpy="1.5708 2.26893 0"/>
      <parent link="leg_front_r_2"/>
      <child link="leg_front_r_3"/>
      <axis xyz="0 0 1.0"/>
      <limit lower="-3.14159" upper="1.20428" effort="3.7" velocity="47.12389"/>
    </joint>

    <material name="ABS_(White)">
      <color rgba="0.96471 0.96471 0.95294 1.0"/>
    </material>

    <material name="Plastic_-_Matte_(Gray)">
      <color rgba="0.70196 0.70196 0.70196 1.0"/>
    </material>

    <material name="Plastic_-_Matte_(White)">
      <color rgba="0.62745 0.83922 1.0 1.0"/>
    </material>

    <material name="Polyurethane">
      <color rgba="0 0 0 1.0"/>
    </material>

    <material name="Steel_-_Satin">
      <color rgba="0.62745 0.62745 0.62745 1.0"/>
    </material>

  </robot>
